<!-- Generated using Gemini with prompt - "Reach avoid task with mujoco" -->
<!-- Edited by Megnath Ramesh -->

<mujoco model="reach_avoid_task">
    <compiler angle="radian"/>
    <option timestep="0.005">
        <flag warmstart="enable"/>
    </option>

    <visual>
        <rgba contactforce="0.8 0.1 0.1 1"/>
        <map znear="0.01"/>
    </visual>

    <asset>
        <texture name="grid" type="2d" builtin="checker" rgb1="0.1 0.2 0.3" rgb2="0.2 0.3 0.4" width="300" height="300" mark="edge" markrgb="0.8 0.8 0.8"/>
        <material name="grid_mat" texture="grid" texrepeat="1 1" texuniform="true"/>
        <material name="blue_mat" rgba="0.2 0.2 0.8 1"/>
        <material name="red_mat" rgba="0.8 0.2 0.2 1"/>
        <material name="green_mat" rgba="0.2 0.8 0.2 1"/>
    </asset>

    <worldbody>
        <geom name="floor" type="plane" size="0 0 0.1" material="grid_mat"/>

        <body name="base" pos="0 0 0.5">
            <geom name="base_link" type="sphere" size="0.05" material="blue_mat"/>

            <body name="link1" pos="0 0 0.1">
                <joint name="joint1" type="hinge" axis="0 0 1" pos="0 0 0"/>
                <geom name="link1_geom" type="capsule" size="0.04" fromto="0 0 0 0 0 0.2" material="blue_mat"/>

                <body name="link2" pos="0 0 0.2">
                    <joint name="joint2" type="hinge" axis="0 1 0" pos="0 0 0"/>
                    <geom name="link2_geom" type="capsule" size="0.03" fromto="0 0 0 0 0 0.2" material="blue_mat"/>
                    <site name="end_effector" pos="0 0 0.2" size="0.01" type="sphere" rgba="1 1 0 1"/>
                </body>
            </body>
        </body>

        <body name="target" pos="0.3 0.3 0.3">
            <geom name="target_geom" type="sphere" size="0.05" material="green_mat" contype="0" conaffinity="0"/>
        </body>

        <body name="obstacle" pos="-0.2 -0.2 0.4">
            <geom name="obstacle_geom" type="sphere" size="0.08" material="red_mat" contype="1" conaffinity="1"/>
        </body>
    </worldbody>

    <actuator>
        <motor name="motor1" joint="joint1" gear="100"/>
        <motor name="motor2" joint="joint2" gear="100"/>
    </actuator>
</mujoco>